Workbook

Sheet Crop Prices (2022-2024) (2)
A1: WHOLESALE PRICES - CONVENTIONAL
A2: Crop | B2: Type | C2: Year | D2: Unit | E2: Unit type | F2: Average Price ($) | G2: Average price ($/lb) | H2: Source | I2: Notes
A3: Green beans (Vancouver) | B3: Conventional Wholesale - CTN 20 LBS | C3: 2022 | D3: 20 | E3: lbs | F3: 40.85 | G3: =F3/D3 -> 2.0425 | H3: Agriculture & Agri-Food Canada | I3: Used green bean prices as proxy for purple beans
A4: Green beans (Vancouver) | B4: Conventional Wholesale - CTN 20 LBS | C4: 2023 | D4: 20 | E4: lbs | F4: 43.25 | G4: =F4/D4 -> 2.1625 | H4: Agriculture & Agri-Food Canada
A5: Green beans (Vancouver) | B5: Conventional Wholesale - CTN 20 LBS | C5: 2024 | D5: 20 | E5: lbs | F5: 44.5 | G5: =F5/D5 -> 2.225 | H5: Agriculture & Agri-Food Canada
A6: Carrots (Vancouver) | B6: Conventional Wholesale - unspecified Ctn 10x5 lbs BC | C6: 2022 | D6: 50 | E6: lbs | F6: 40.375 | G6: =F6/D6 -> 0.8075 | H6: Agriculture & Agri-Food Canada | I6: Used the unspecified prices as the tops were removed. Used 10x5 lbs line - not available for 2024
A7: Carrots (Vancouver) | B7: Conventional Wholesale - unspecified Ctn 10x5 lbs BC | C7: 2023 | D7: 50 | E7: lbs | F7: 46.475 | G7: =F7/D7 -> 0.9295 | H7: Agriculture & Agri-Food Canada | I7: Used the unspecified prices as the tops were removed. Used 10x5 lbs line - doesn't cover all three years
A8: Carrots (Vancouver) | B8: Conventional Wholesale - unspecified Bag 24x2 lbs BC | C8: 2024 | D8: 48 | E8: lbs | F8: 66.25 | G8: =F8/D8 -> 1.3802083 | H8: Agriculture & Agri-Food Canada | I8: Used the unspecified prices as the tops were removed. Used 24 x 2 lbs bag line - not available for 2022
A9: Kale (Vancouver) | B9: Conventional Wholesale - 24 CT | C9: 2022 | D9: 20 | E9: lbs | F9: 26.85 | G9: =F9/D9 -> 1.3425 | H9: Agriculture & Agri-Food Canada | I9: Used conventional green kale prices (no Red Russian). Assumed that 24CT = 20# (based on Organic BC reporting)
A10: Kale (Vancouver) | B10: Conventional Wholesale - 24 CT | C10: 2023 | D10: 20 | E10: lbs | F10: 30.15 | G10: =F10/D10 -> 1.5075 | H10: Agriculture & Agri-Food Canada
A11: Kale (Vancouver) | B11: Conventional Wholesale - 24 CT | C11: 2024 | D11: 20 | E11: lbs | F11: 28.5 | G11: =F11/D11 -> 1.425 | H11: Agriculture & Agri-Food Canada
A13: WHOLESALE PRICES - ORGANIC
A14: Organic Crops | B14: Type | C14: Year | D14: Unit | E14: Unit type | F14: Average Price ($) | G14: Average price ($/lb)
A15: Green beans (BC) | B15: Organic Wholesale - green bulk 20# BC | C15: 2022 | D15: 20 | E15: lbs | F15: 65.4 | G15: =F15/D15 -> 3.27 | H15: Organic BC - SEP 2022 | I15: Used September data as this was when most of the crops were harvested. Used green instead of purple beans.
A16: Green beans (BC) | B16: Organic Wholesale - green bulk 20# BC | C16: 2023 | D16: 20 | E16: lbs | F16: 71.5 | G16: =F16/D16 -> 3.575 | H16: Organic BC - AUG 2023 | I16: Used August data - no September available. Used green instead of purple beans.
A17: Green beans (BC) | B17: Organic Wholesale - green bulk 20# BC | C17: 2024 | D17: 20 | E17: lbs | F17: 59.8 | G17: =F17/D17 -> 2.99 | H17: Organic BC - SEP 2024 | I17: Used September data as this was when most of the crops were harvested. Used green instead of purple beans.
A18: Carrots (BC) | B18: Organic Wholesale - table 25# BC | C18: 2022 | D18: 25 | E18: lbs | F18: 52.1 | G18: =F18/D18 -> 2.084 | H18: Organic BC - SEP 2022 | I18: Used September data as this was when most of the crops were harvested. Looked at table carrots.
A19: Carrots (BC) | B19: Organic Wholesale - table 25# BC | C19: 2023 | D19: 25 | E19: lbs | F19: 58.8 | G19: =F19/D19 -> 2.352 | H19: Organic BC - AUG 2023 | I19: Used August data - no September available. Looked at table carrots.
A20: Carrots (BC) | B20: Organic Wholesale - table 25# CA | C20: 2024 | D20: 25 | E20: lbs | F20: 58.1 | G20: =F20/D20 -> 2.324 | H20: Organic BC - SEP 2024 | I20: Used September data as this was when most of the crops were harvested. Looked at table carrots - no BC.
A21: Kale (BC) | B21: Organic Wholesale - green curly 24CT BC | C21: 2022 | D21: 20 | E21: lbs | F21: 64.2 | G21: =F21/D21 -> 3.21 | H21: Organic BC - SEP 2022 | I21: Used September data for green curly kale (no red Russian).
A22: Kale (BC) | B22: Organic Wholesale - green curly 24CT BC | C22: 2023 | D22: 20 | E22: lbs | F22: 68.4 | G22: =F22/D22 -> 3.42 | H22: Organic BC - AUG 2023 | I22: Used August data for green curly kale (no red Russian).
A23: Kale (BC) | B23: Organic Wholesale - green curly 24CT BC | C23: 2024 | D23: 20 | E23: lbs | F23: 57.2 | G23: =F23/D23 -> 2.86 | H23: Organic BC - SEP 2024 | I23: Used September data for green curly kale (no red Russian).
A25: DIRECT MARKETING PRICES - CONVENTIONAL
A26: Crop | B26: Type | C26: Year | D26: Unit | E26: Unit type | F26: Average Price ($) | G26: Average price ($/lb) | H26: Source | I26: Notes
A27: Green beans | B27: Conventional Direct Marketing | C27: 2022 | D27: 1 | E27: lbs | F27: =(F3*1.7)/20 -> 3.47225 | G27: =F27/D27 -> 3.47225 | H27: Conventional wholesale numbers * 1.7 | I27: I multiplied the wholesale average price by 1.7 and divided by the unit number to get this price.
A28: Green beans | B28: Conventional Direct Marketing | C28: 2023 | D28: 1 | E28: lbs | F28: =(F4*1.7)/20 -> 3.67625 | G28: =F28/D28 -> 3.67625 | H28: Conventional wholesale numbers * 1.7
A29: Green beans | B29: Conventional Direct Marketing | C29: 2024 | D29: 1 | E29: lbs | F29: =(F5*1.7)/20 -> 3.7825 | G29: =F29/D29 -> 3.7825 | H29: Conventional wholesale numbers * 1.7
A30: Carrots | B30: Conventional Direct Marketing | C30: 2022 | D30: 1 | E30: lbs | F30: =(F6*1.7)/20 -> 3.431875 | G30: =F30/D30 -> 3.431875 | H30: Conventional wholesale numbers * 1.7
A31: Carrots | B31: Conventional Direct Marketing | C31: 2023 | D31: 1 | E31: lbs | F31: =(F7*1.7)/20 -> 3.950375 | G31: =F31/D31 -> 3.950375 | H31: Conventional wholesale numbers * 1.7
A32: Carrots | B32: Conventional Direct Marketing | C32: 2024 | D32: 1 | E32: lbs | F32: =(F8*1.7)/20 -> 5.63125 | G32: =F32/D32 -> 5.63125 | H32: Conventional wholesale numbers * 1.7
A33: Kale | B33: Conventional Direct Marketing | C33: 2022 | D33: 1 | E33: lbs | F33: =(F9*1.7)/20 -> 2.28225 | G33: =F33/D33 -> 2.28225 | H33: Conventional wholesale numbers * 1.7
A34: Kale | B34: Conventional Direct Marketing | C34: 2023 | D34: 1 | E34: lbs | F34: =(F10*1.7)/20 -> 2.56275 | G34: =F34/D34 -> 2.56275 | H34: Conventional wholesale numbers * 1.7
A35: Kale | B35: Conventional Direct Marketing | C35: 2024 | D35: 1 | E35: lbs | F35: =(F11*1.7)/20 -> 2.4225 | G35: =F35/D35 -> 2.4225 | H35: Conventional wholesale numbers * 1.7
A37: DIRECT MARKETING PRICES - ORGANIC
A38: Organic Crop | B38: Type | C38: Year | D38: Unit | E38: Unit type | F38: Average Price ($) | G38: Average price ($/lb) | H38: Source | I38: Notes
A39: Green beans | B39: Organic Direct Marketing | C39: 2022 | D39: 1 | E39: lbs | F39: =(F15*1.8)/D15 -> 5.886 | G39: =F39/D39 -> 5.886 | H39: Organic wholesale numbers * 1.8 | I39: I multiplied the wholesale average price by 1.8 and divided by the unit number to get this price.
A40: Green beans | B40: Organic Direct Marketing | C40: 2023 | D40: 1 | E40: lbs | F40: =(F16*1.8)/D16 -> 6.435 | G40: =F40/D40 -> 6.435 | H40: Organic wholesale numbers * 1.8
A41: Green beans | B41: Organic Direct Marketing | C41: 2024 | D41: 1 | E41: lbs | F41: =(F17*1.8)/D17 -> 5.382 | G41: =F41/D41 -> 5.382 | H41: Organic wholesale numbers * 1.8
A42: Carrots | B42: Organic Direct Marketing | C42: 2022 | D42: 1 | E42: lbs | F42: =(F18*1.8)/D18 -> 3.7512 | G42: =F42/D42 -> 3.7512 | H42: Organic wholesale numbers * 1.8
A43: Carrots | B43: Organic Direct Marketing | C43: 2023 | D43: 1 | E43: lbs | F43: =(F19*1.8)/D19 -> 4.2336 | G43: =F43/D43 -> 4.2336 | H43: Organic wholesale numbers * 1.8
...

Sheet Financial Data (R)
A1: Number | B1: Year | C1: Treatment | D1: Replicate | E1: Inorganic Fertilizer | F1: Tillage | G1: Cover crops | H1: Compost | I1: Grazing | J1: Bean Harvest (g) | K1: Carrot Gr. 1 Harvest (g) | L1: Kale Harvest (g) | M1: Total Harvest (g) | N1: Total Revenue - Wholesale ($) | O1: Total Revenue - Direct Marketing ($) | P1: Total Revenue - Wholesale 33% Sort Outs ($) | Q1: Total Revenue - Direct Marketing 20% Unsold ($) | R1: Total Annual Variable Cost - Wholesale ($) | S1: Total Annual Variable Cost - Direct Marketing ($) | T1: Total Annual Labour Cost - Wholesale ($) | U1: Labour Cost - Land Preparation ($) | V1: Labour Cost - Planting ($) | W1: Labour Cost - Weeding ($) | X1: Labour Cost - Bean Harvest ($) | Y1: Labour Cost - Carrot Harvest ($) | Z1: Labour Cost - Kale Harvest ($) | AA1: Labour Cost - Livestock Management ($) | AB1: Total Annual Labour Cost - Direct Marketing ($) | AC1: Total Annual Input Cost ($) | AD1: Net Returns Over Variable Cost - Wholesale ($) | AE1: Net Returns Over Variable Cost - Direct Marketing ($) | AF1: Net Returns Over Variable Cost - Wholesale 33% Sort Outs ($) | AG1: Net Returns Over Variable Cost - Direct Marketing 20% Unsold ($)
A2: 1 | B2: 2022 | C2: 1 | D2: 1 | E2: Yes | F2: Yes | G2: No | H2: No | I2: No | J2: 3247.3 | K2: 1689.2 | L2: 30.2 | M2: =SUM(J2:L2) -> 4966.7 | N2: {=TRANSPOSE('Cost-Benefit Analysis 2022'!B10:U10)} -> 17.718955 | O2: {=TRANSPOSE('Cost-Benefit Analysis 2022'!B11:U11)} -> 30.122223 | P2: {=TRANSPOSE('Cost-Benefit Analysis 2022'!B12:U12)} -> 11.812637 | Q2: {=TRANSPOSE('Cost-Benefit Analysis 2022'!B13:U13)} -> 24.097779 | R2: {=TRANSPOSE('Cost-Benefit Analysis 2022'!B43:U43)} -> 33.915989 | S2: {=TRANSPOSE('Cost-Benefit Analysis 2022'!B44:U44)} -> 40.029028 | T2: {=TRANSPOSE('Cost-Benefit Analysis 2022'!B41:U41)} -> 25.561667 | U2: {=TRANSPOSE('Cost-Benefit Analysis 2022'!B18:U18)} -> 7.1077083 | V2: {=TRANSPOSE('Cost-Benefit Analysis 2022'!B26:U26)} -> 0 | W2: {=TRANSPOSE('Cost-Benefit Analysis 2022'!B28:U28)} -> 11.998333 | X2: {=TRANSPOSE('Cost-Benefit Analysis 2022'!B30:U30)} -> 4.9558333 | Y2: {=TRANSPOSE('Cost-Benefit Analysis 2022'!B31:U31)} -> 1.0433333 | Z2: {=TRANSPOSE('Cost-Benefit Analysis 2022'!B32:U32)} -> 0.45645833 | AA2: {=TRANSPOSE('Cost-Benefit Analysis 2022'!B34:U34)} -> 0 | AB2: {=TRANSPOSE('Cost-Benefit Analysis 2022'!B42:U42)} -> 25.561667 | AC2: {=TRANSPOSE('Cost-Benefit Analysis 2022'!B40:U40)} -> 1.67875 | AD2: {=TRANSPOSE('Cost-Benefit Analysis 2022'!B47:U47)} -> -16.197034 | AE2: {=TRANSPOSE('Cost-Benefit Analysis 2022'!B48:U48)} -> -9.9068048 | AF2: {=TRANSPOSE('Cost-Benefit Analysis 2022'!B49:U49)} -> -22.103352 | AG2: {=TRANSPOSE('Cost-Benefit Analysis 2022'!B50:U50)} -> -15.931249
A3: 2 | B3: 2022 | C3: 1 | D3: 2 | E3: Yes | F3: Yes | G3: No | H3: No | I3: No | J3: 3715.1 | K3: 4814.5 | L3: 49.8 | M3: =SUM(J3:L3) -> 8579.4 | N3: 25.447203 | O3: 43.260245 | P3: 16.964802 | Q3: 34.608196 | R3: 37.999926 | S3: 46.779211 | T3: 27.713542 | U3: 7.1077083 | V3: 0 | W3: 10.1725 | X3: 5.4775 | Y3: 4.4341667 | Z3: 0.52166667 | AA3: 0 | AB3: 27.713542 | AC3: 1.67875 | AD3: -12.552723 | AE3: -3.518966 | AF3: -21.035124 | AG3: -12.171015
A4: 3 | B4: 2022 | C4: 1 | D4: 3 | E4: Yes | F4: Yes | G4: No | H4: No | I4: No | J4: 3278.9 | K4: 1862.1 | L4: 48.5 | M4: =SUM(J4:L4) -> 5189.5 | N4: 18.223213 | O4: 30.979462 | P4: 12.148808 | Q4: 24.783569 | R4: 37.106845 | S4: 43.393853 | T4: 28.626458 | U4: 7.1077083 | V4: 0 | W4: 13.041667 | X4: 4.695 | Y4: 3.3908333 | Z4: 0.39125 | AA4: 0 | AB4: 28.626458 | AC4: 1.67875 | AD4: -18.883632 | AE4: -12.414392 | AF4: -24.958036 | AG4: -18.610284
A5: 4 | B5: 2022 | C5: 1 | D5: 4 | E5: Yes | F5: Yes | G5: No | H5: No | I5: No | J5: 3817.4 | K5: 4125.3 | L5: 56.7 | M5: =SUM(J5:L5) -> 7999.4 | N5: 24.701339 | O5: 41.992277 | P5: 16.467559 | Q5: 33.593821 | R5: 45.312418 | S5: 53.83438 | T5: 35.2125 | U5: 7.1077083 | V5: 0 | W5: 18.519167 | X5: 5.4775 | Y5: 3.6516667 | Z5: 0.45645833 | AA5: 0 | AB5: 35.2125 | AC5: 1.67875 | AD5: -20.611079 | AE5: -11.842103 | AF5: -28.844859 | AG5: -20.240559
A6: 5 | B6: 2022 | C6: 2 | D6: 1 | E6: Yes | F6: Yes | G6: Yes | H6: No | I6: No | J6: 2610.8 | K6: 3185.6 | L6: 62.5 | M6: =SUM(J6:L6) -> 5858.9 | N6: 17.612371 | O6: 29.941031 | P6: 11.741581 | Q6: 23.952825 | R6: 37.361218 | S6: 43.437486 | T6: 26.148542 | U6: 7.1077083 | V6: 0.39125 | W6: 11.998333 | X6: 3.9125 | Y6: 2.3475 | Z6: 0.39125 | AA6: 0 | AB6: 26.148542 | AC6: 4.56375 | AD6: -19.748847 | AE6: -13.496455 | AF6: -25.619637 | AG6: -19.484661
A7: 6 | B7: 2022 | C7: 2 | D7: 2 | E7: Yes | F7: Yes | G7: Yes | H7: No | I7: No | J7: 2854.6 | K7: 2558.5 | L7: 25.5 | M7: =SUM(J7:L7) -> 5438.6 | N7: 17.484295 | O7: 29.723302 | P7: 11.656197 | Q7: 23.778642 | R7: 43.915241 | S7: 49.947322 | T7: 32.734583 | U7: 7.1077083 | V7: 0.39125 | W7: 18.258333 | X7: 4.4341667 | Y7: 2.0866667 | Z7: 0.45645833 | AA7: 0 | AB7: 32.734583 | AC7: 4.56375 | AD7: -26.430945 | AE7: -20.22402 | AF7: -32.259044 | AG7: -26.168681
A8: 7 | B8: 2022 | C8: 2 | D8: 3 | E8: Yes | F8: Yes | G8: Yes | H8: No | I8: No | J8: 2594.8 | K8: 4424.3 | L8: 54.2 | M8: =SUM(J8:L8) -> 7073.3 | N8: 19.720933 | O8: 33.525586 | P8: 13.147289 | Q8: 26.820469 | R8: 43.30065 | S8: 50.104372 | T8: 31.560833 | U8: 7.1077083 | V8: 0.39125 | W8: 16.954167 | X8: 4.1733333 | Y8: 2.6083333 | Z8: 0.32604167 | AA8: 0 | AB8: 31.560833 | AC8: 4.56375 | AD8: -23.579717 | AE8: -16.578786 | AF8: -30.153361 | AG8: -23.283903
A9: 8 | B9: 2022 | C9: 2 | D9: 4 | E9: Yes | F9: Yes | G9: Yes | H9: No | I9: No | J9: 3891.4 | K9: 2473.9 | L9: 30.4 | M9: =SUM(J9:L9) -> 6395.7 | N9: 22.01684 | O9: 37.428628 | P9: 14.677894 | Q9: 29.942903 | R9: 40.092543 | S9: 47.688353 | T9: 27.77875 | U9: 7.1077083 | V9: 0.39125 | W9: 11.7375 | X9: 6.26 | Y9: 1.8258333 | Z9: 0.45645833 | AA9: 0 | AB9: 27.77875 | AC9: 4.56375 | AD9: -18.075703 | AE9: -10.259725 | AF9: -25.41465 | AG9: -17.745451
A10: 9 | B10: 2022 | C10: 3 | D10: 1 | E10: No | F10: Yes | G10: Yes | H10: Yes | I10: No | J10: 2536.2 | K10: 1919.2 | L10: 42.1 | M10: =SUM(J10:L10) -> 4497.5 | N10: 27.399332 | O10: 49.318797 | P10: 18.266221 | Q10: 39.455038 | R10: 64.443583 | S10: 74.855329 | T10: 32.212917 | U10: 8.411875 | V10: 0.39125 | W10: 17.736667 | X10: 3.9125 | Y10: 1.3041667 | Z10: 0.45645833 | AA10: 0 | AB10: 32.212917 | AC10: 23.135 | AD10: -37.044251 | AE10: -25.536532 | AF10: -46.177362 | AG10: -35.400291
A11: 10 | B11: 2022 | C11: 3 | D11: 2 | E11: No | F11: Yes | G11: Yes | H11: Yes | I11: No | J11: 2176 | K11: 2085.2 | L11: 38.2 | M11: =SUM(J11:L11) -> 4299.4 | N11: 25.537684 | O11: 45.967832 | P11: 17.025123 | Q11: 36.774266 | R11: 66.912546 | S11: 76.616866 | T11: 35.147292 | U11: 8.411875 | V11: 0.39125 | W11: 21.1275 | X11: 3.3908333 | Y11: 1.3041667 | Z11: 0.52166667 | AA11: 0 | AB11: 35.147292 | AC11: 23.135 | AD11: -41.374862 | AE11: -30.649034 | AF11: -49.887423 | AG11: -39.842601
A12: 11 | B12: 2022 | C12: 3 | D12: 3 | E12: No | F12: Yes | G12: Yes | H12: Yes | I12: No | J12: 4021.8 | K12: 3142.1 | L12: 58.1 | M12: =SUM(J12:L12) -> 7222 | N12: 43.840957 | O12: 78.913722 | P12: 29.227304 | Q12: 63.130977 | R12: 63.141697 | S12: 79.801261 | T12: 26.800625 | U12: 8.411875 | V12: 0.39125 | W12: 9.39 | X12: 6.26 | Y12: 1.8258333 | Z12: 0.52166667 | AA12: 0 | AB12: 26.800625 | AC12: 23.135 | AD12: -19.300741 | AE12: -0.88753913 | AF12: -33.914393 | AG12: -16.670284
A13: 12 | B13: 2022 | C13: 3 | D13: 4 | E13: No | F13: Yes | G13: Yes | H13: Yes | I13: No | J13: 3052.1 | K13: 1884.5 | L13: 58.2 | M13: =SUM(J13:L13) -> 4994.8 | N13: 31.073025 | O13: 55.931445 | P13: 20.71535 | Q13: 44.745156 | R13: 67.18784 | S13: 78.995589 | T13: 34.03875 | U13: 8.411875 | V13: 0.39125 | W13: 19.5625 | X13: 4.1733333 | Y13: 1.0433333 | Z13: 0.45645833 | AA13: 0 | AB13: 34.03875 | AC13: 23.135 | AD13: -36.114815 | AE13: -23.064144 | AF13: -46.47249 | AG13: -34.250433
A14: 13 | B14: 2022 | C14: 4 | D14: 1 | E14: No | F14: Yes | G14: Yes | H14: Yes | I14: Yes | J14: 3237.7 | K14: 2724.2 | L14: 47.8 | M14: =SUM(J14:L14) -> 6009.7 | N14: 36.195384 | O14: 65.15169 | P14: 24.130256 | Q14: 52.121352 | R14: 60.839054 | S14: 74.5933 | T14: 26.409375 | U14: 8.411875 | V14: 0.39125 | W14: 10.955 | X14: 4.9558333 | Y14: 1.3041667 | Z14: 0.39125 | AA14: 0 | AB14: 26.409375 | AC14: 23.135 | AD14: -24.643671 | AE14: -9.4416096 | AF14: -36.708799 | AG14: -22.471948
... A21: 20 | B21: 2022 | C21: 5 | D21: 4 | E21: No | F21: No | G21: Yes | H21: Yes | I21: Yes | J21: 3500.6 | K21: 3023.3 | L21: 73.4 | M21: =SUM(J21:L21) -> 6597.3 | N21: 39.646022 | O21: 71.36284 | P21: 26.430682 | Q21: 57.090272 | R21: 60.267131 | S21: 75.332619 | T21: 24.974792 | U21: 8.411875 | V21: 0.39125 | W21: 8.8683333 | X21: 5.2166667 | Y21: 1.3041667 | Z21: 0.7825 | AA21: 0 | AB21: 24.974792 | AC21: 23.135 | AD21: -20.621108 | AE21: -3.969779 | AF21: -33.836449 | AG21: -18.242347
A22: 21 | B22: 2023 | C22: 1 | D22: 1 | E22: Yes | F22: Yes | G22: No | H22: No | I22: No | J22: 4597.3 | K22: 3881.2 | L22: 537.8 | M22: =SUM(J22:L22) -> 9016.3 | N22: {=TRANSPOSE('Cost-Benefit Analysis 2023'!B10:U10)} -> 31.658315 | O22: {=TRANSPOSE('Cost-Benefit Analysis 2023'!B11:U11)} -> 53.819136 | P22: {=TRANSPOSE('Cost-Benefit Analysis 2023'!B12:U12)} -> 21.105543 | Q22: {=TRANSPOSE('Cost-Benefit Analysis 2023'!B13:U13)} -> 43.055308 | R22: {=TRANSPOSE('Cost-Benefit Analysis 2023'!B43:U43)} -> 76.924969 | S22: {=TRANSPOSE('Cost-Benefit Analysis 2023'!B44:U44)} -> 87.847088 | T22: {=TRANSPOSE('Cost-Benefit Analysis 2023'!B41:U41)} -> 60.465755 | U22: {=TRANSPOSE('Cost-Benefit Analysis 2023'!B18:U18)} -> 5.1907552 | V22: {=TRANSPOSE('Cost-Benefit Analysis 2023'!B26:U26)} -> 0 | W22: {=TRANSPOSE('Cost-Benefit Analysis 2023'!B28:U28)} -> 34.477083 | X22: {=TRANSPOSE('Cost-Benefit Analysis 2023'!B30:U30)} -> 13.4 | Y22: {=TRANSPOSE('Cost-Benefit Analysis 2023'!B31:U31)} -> 4.3270833 | Z22: {=TRANSPOSE('Cost-Benefit Analysis 2023'!B32:U32)} -> 3.0708333 | AA22: {=TRANSPOSE('Cost-Benefit Analysis 2023'!B34:U34)} -> 0 | AB22: {=TRANSPOSE('Cost-Benefit Analysis 2023'!B42:U42)} -> 60.465755 | AC22: {=TRANSPOSE('Cost-Benefit Analysis 2023'!B40:U40)} -> 1.67875 | AD22: {=TRANSPOSE('Cost-Benefit Analysis 2023'!B47:U47)} -> -45.266654 | AE22: {=TRANSPOSE('Cost-Benefit Analysis 2023'!B48:U48)} -> -34.027953 | AF22: {=TRANSPOSE('Cost-Benefit Analysis 2023'!B49:U49)} -> -55.819426 | AG22: {=TRANSPOSE('Cost-Benefit Analysis 2023'!B50:U50)} -> -44.79178
A23: 22 | B23: 2023 | C23: 1 | D23: 2 | E23: Yes | F23: Yes | G23: No | H23: No | I23: No | J23: 5548.2 | K23: 6626.2 | L23: 1769.5 | M23: =SUM(J23:L23) -> 13943.9 | N23: 45.910289 | O23: 78.047491 | P23: 30.606859 | Q23: 62.437993 | R23: 75.788657 | S23: 91.627707 | T23: 55.76645 | U23: 5.1907552 | V23: 0 | W23: 26.218403 | X23: 12.283333 | Y23: 6.8395833 | Z23: 5.234375 | AA23: 0 | AB23: 55.76645 | AC23: 1.67875 | AD23: -29.878369 | AE23: -13.580216 | AF23: -45.181798 | AG23: -29.189714
A24: 23 | B24: 2023 | C24: 1 | D24: 3 | E24: Yes | F24: Yes | G24: No | H24: No | I24: No | J24: 7776.3 | K24: 7038.2 | L24: 856.2 | M24: =SUM(J24:L24) -> 15670.7 | N24: 54.341693 | O24: 92.380877 | P24: 36.227795 | Q24: 73.904702 | R24: 73.313522 | S24: 92.061406 | T24: 51.183464 | U24: 5.1907552 | V24: 0 | W24: 22.19375 | X24: 15.005208 | Y24: 4.6760417 | Z24: 4.1177083 | AA24: 0 | AB24: 51.183464 | AC24: 1.67875 | AD24: -18.971829 | AE24: 0.3194714 | AF24: -37.085727 | AG24: -18.156704
A25: 24 | B25: 2023 | C25: 1 | D25: 4 | E25: Yes | F25: Yes | G25: No | H25: No | I25: No | J25: 4944.4 | K25: 5829.2 | L25: 959.2 | M25: =SUM(J25:L25) -> 11732.8 | N25: 38.705458 | O25: 65.799279 | P25: 25.803639 | Q25: 52.639423 | R25: 75.008734 | S25: 88.362117 | T25: 56.787734 | U25: 5.1907552 | V25: 0 | W25: 30.170938 | X25: 11.096875 | Y25: 6.0020833 | Z25: 4.3270833 | AA25: 0 | AB25: 56.787734 | AC25: 1.67875 | AD25: -36.303276 | AE25: -22.562839 | AF25: -49.205096 | AG25: -35.722694
A26: 25 | B26: 2023 | C26: 2 | D26: 1 | E26: Yes | F26: Yes | G26: Yes | H26: No | I26: No | J26: 4342.5 | K26: 6182.4 | L26: 1879.1 | M26: =SUM(J26:L26) -> 12404 | N26: 39.616937 | O26: 67.348793 | P26: 26.411291 | Q26: 53.879034 | R26: 68.975406 | S26: 82.643249 | T26: 47.641536 | U26: 5.1907552 | V26: 0.41875 | W26: 21.792448 | X26: 9.4916667 | Y26: 5.5833333 | Z26: 5.1645833 | AA26: 0 | AB26: 47.641536 | AC26: 4.56375 | AD26: -29.358469 | AE26: -15.294457 | AF26: -42.564115 | AG26: -28.764215
A27: 26 | B27: 2023 | C27: 2 | D27: 2 | E27: Yes | F27: Yes | G27: Yes | H27: No | I27: No | J27: 7257.3 | K27: 4988.9 | L27: 751.2 | M27: =SUM(J27:L27) -> 12997.4 | N27: 47.318979 | O27: 80.442264 | P27: 31.545986 | Q27: 64.353811 | R27: 77.939406 | S27: 94.264454 | T27: 54.680026 | U27: 5.1907552 | V27: 0.41875 | W27: 24.783021 | X27: 15.772917 | Y27: 3.978125 | Z27: 4.5364583 | AA27: 0 | AB27: 54.680026 | AC27: 4.56375 | AD27: -30.620427 | AE27: -13.82219 | AF27: -46.39342 | AG27: -29.910643
A28: 27 | B28: 2023 | C28: 2 | D28: 3 | E28: Yes | F28: Yes | G28: Yes | H28: No | I28: No | J28: 6263.2 | K28: 4164 | L28: 1908.1 | M28: =SUM(J28:L28) -> 12335.3 | N28: 44.734149 | O28: 76.048054 | P28: 29.822766 | Q28: 60.838443 | R28: 80.21747 | S28: 95.650751 | T28: 57.604297 | U28: 5.1907552 | V28: 0.41875 | W28: 28.684375 | X28: 13.609375 | Y28: 4.3270833 | Z28: 5.3739583 | AA28: 0 | AB28: 57.604297 | AC28: 4.56375 | AD28: -35.48332 | AE28: -19.602697 | AF28: -50.394703 | AG28: -34.812308
A29: 28 | B29: 2023 | C29: 2 | D29: 4 | E29: Yes | F29: Yes | G29: Yes | H29: No | I29: No | J29: 6946.6 | K29: 6127.5 | L29: 1503.2 | M29: =SUM(J29:L29) -> 14577.3 | N29: 50.670182 | O29: 86.139309 | P29: 33.780121 | Q29: 68.911447 | R29: 79.747311 | S29: 97.228524 | T29: 55.65013 | U29: 5.1907552 | V29: 0.41875 | W29: 24.566667 | X29: 14.028125 | Y29: 7.3979167 | Z29: 4.0479167 | AA29: 0 | AB29: 55.65013 | AC29: 4.56375 | AD29: -29.077129 | AE29: -11.089215 | AF29: -45.96719 | AG29: -28.317077
A30: 29 | B30: 2023 | C30: 3 | D30: 1 | E30: No | F30: Yes | G30: Yes | H30: Yes | I30: No | J30: 4710.9 | K30: 5154.3 | L30: 327.3 | M30: =SUM(J30:L30) -> 10192.5 | N30: 66.323309 | O30: 119.38196 | P30: 44.21554 | Q30: 95.505566 | R30: 105.62283 | S30: 130.82569 | T30: 49.79112 | U30: 6.5865885 | V30: 0.41875 | W30: 26.035781 | X30: 10.259375 | Y30: 3.2802083 | Z30: 3.2104167 | AA30: 0 | AB30: 49.79112 | AC30: 32.385 | AD30: -39.299523 | AE30: -11.443733 | AF30: -61.407293 | AG30: -35.320125
A31: 30 | B31: 2023 | C31: 3 | D31: 2 | E31: No | F31: Yes | G31: Yes | H31: Yes | I31: No | J31: 4455.5 | K31: 3988.8 | L31: 1206.7 | M31: =SUM(J31:L31) -> 9651 | N31: 64.897441 | O31: 116.81539 | P31: 43.264961 | Q31: 93.452315 | R31: 103.51808 | S31: 128.17911 | T31: 48.042839 | U31: 6.5865885 | V31: 0.41875 | W31: 21.077083 | X31: 9.9104167 | Y31: 5.5833333 | Z31: 4.4666667 | AA31: 0 | AB31: 48.042839 | AC31: 32.385 | AD31: -38.620643 | AE31: -11.363718 | AF31: -60.253124 | AG31: -34.726797
A32: 31 | B32: 2023 | C32: 3 | D32: 3 | E32: No | F32: Yes | G32: Yes | H32: Yes | I32: No | J32: 6886.8 | K32: 7913 | L32: 1344.7 | M32: =SUM(J32:L32) -> 16144.5 | N32: 105.44833 | O32: 189.807 | P32: 70.29889 | Q32: 151.8456 | R32: 112.12039 | S32: 152.19076 | T32: 46.507422 | U32: 6.5865885 | V32: 0.41875 | W32: 15.703125 | X32: 14.795833 | Y32: 4.6760417 | Z32: 4.3270833 | AA32: 0 | AB32: 46.507422 | AC32: 32.385 | AD32: -6.6720563 | AE32: 37.616244 | AF32: -41.821501 | AG32: -0.34515627
A33: 32 | B33: 2023 | C33: 3 | D33: 4 | E33: No | F33: Yes | G33: Yes | H33: Yes | I33: No | J33: 5338.5 | K33: 6661.4 | L33: 191.2 | M33: =SUM(J33:L33) -> 12191.1 | N33: 78.058311 | O33: 140.50496 | P33: 52.038874 | Q33: 112.40397 | R33: 109.71164 | S33: 139.37379 | T33: 50.946172 | U33: 6.5865885 | V33: 0.41875 | W33: 24.259583 | X33: 12.283333 | Y33: 4.7458333 | Z33: 2.6520833 | AA33: 0 | AB33: 50.946172 | AC33: 32.385 | AD33: -31.653324 | AE33: 1.1311666 | AF33: -57.672761 | AG33: -26.969825
A34: 33 | B34: 2023 | C34: 4 | D34: 1 | E34: No | F34: Yes | G34: Yes | H34: Yes | I34: Yes | J34: 7562.5 | K34: 5642.2 | L34: 982 | M34: =SUM(J34:L34) -> 14186.7 | N34: 96.264476 | O34: 173.27606 | P34: 64.176317 | Q34: 138.62085 | R34: 130.74448 | S34: 167.32498 | T34: 67.427474 | U34: 7.6334635 | V34: 0.41875 | W34: 20.85026 | X34: 19.122917 | Y34: 5.3041667 | Z34: 3.6291667 | AA34: 10.46875 | AB34: 67.427474 | AC34: 32.385 | AD34: -34.480002 | AE34: 5.9510778 | AF34: -66.568161 | AG34: -28.704134
... A41: 40 | B41: 2023 | C41: 5 | D41: 4 | E41: No | F41: No | G41: Yes | H41: Yes | I41: Yes | J41: 7099.5 | K41: 4564.2 | L41: 1006.9 | M41: =SUM(J41:L41) -> 12670.6 | N41: 87.213347 | O41: 156.98403 | P41: 58.142232 | Q41: 125.58722 | R41: 115.95943 | S41: 149.1005 | T41: 60.771094 | U41: 13.522135 | V41: 0.41875 | W41: 11.585417 | X41: 17.727083 | Y41: 2.7916667 | Z41: 4.2572917 | AA41: 10.46875 | AB41: 60.771094 | AC41: 32.385 | AD41: -28.746083 | AE41: 7.8835226 | AF41: -57.817199 | AG41: -23.513282
A42: 41 | B42: 2024 | C42: 1 | D42: 1 | E42: Yes | F42: Yes | G42: No | H42: No | I42: No | J42: 912 | K42: 6487.9 | L42: 521.2 | M42: =SUM(J42:L42) -> 7921.1 | N42: {=TRANSPOSE('Cost-Benefit Analysis 2024'!B10:U10)} -> 15.721093 | O42: {=TRANSPOSE('Cost-Benefit Analysis 2024'!B11:U11)} -> 26.725858 | P42: {=TRANSPOSE('Cost-Benefit Analysis 2024'!B12:U12)} -> 10.480729 | Q42: {=TRANSPOSE('Cost-Benefit Analysis 2024'!B13:U13)} -> 21.380686 | R42: {=TRANSPOSE('Cost-Benefit Analysis 2024'!B43:U43)} -> 104.46637 | S42: {=TRANSPOSE('Cost-Benefit Analysis 2024'!B44:U44)} -> 109.89014 | T42: {=TRANSPOSE('Cost-Benefit Analysis 2024'!B41:U41)} -> 91.522188 | U42: {=TRANSPOSE('Cost-Benefit Analysis 2024'!B18:U18)} -> 5.3921875 | V42: {=TRANSPOSE('Cost-Benefit Analysis 2024'!B26:U26)} -> 0 | W42: {=TRANSPOSE('Cost-Benefit Analysis 2024'!B28:U28)} -> 65.9025 | X42: {=TRANSPOSE('Cost-Benefit Analysis 2024'!B30:U30)} -> 5.51 | Y42: {=TRANSPOSE('Cost-Benefit Analysis 2024'!B31:U31)} -> 7.6125 | Z42: {=TRANSPOSE('Cost-Benefit Analysis 2024'!B32:U32)} -> 7.105 | AA42: {=TRANSPOSE('Cost-Benefit Analysis 2024'!B34:U34)} -> 0 | AB42: {=TRANSPOSE('Cost-Benefit Analysis 2024'!B42:U42)} -> 91.522188 | AC42: {=TRANSPOSE('Cost-Benefit Analysis 2024'!B40:U40)} -> 1.67875 | AD42: {=TRANSPOSE('Cost-Benefit Analysis 2024'!B47:U47)} -> -88.745274 | AE42: {=TRANSPOSE('Cost-Benefit Analysis 2024'!B48:U48)} -> -83.164286 | AF42: {=TRANSPOSE('Cost-Benefit Analysis 2024'!B49:U49)} -> -93.985638 | AG42: {=TRANSPOSE('Cost-Benefit Analysis 2024'!B50:U50)} -> -88.509458
A43: 42 | B43: 2024 | C43: 1 | D43: 2 | E43: Yes | F43: Yes | G43: No | H43: No | I43: No | J43: 2653.8 | K43: 5297.4 | L43: 994.1 | M43: =SUM(J43:L43) -> 8945.3 | N43: 23.98737 | O43: 40.778529 | P43: 15.99158 | Q43: 32.622824 | R43: 91.090436 | S43: 99.366079 | T43: 76.079687 | U43: 5.3921875 | V43: 0 | W43: 44.95 | X43: 9.425 | Y43: 9.135 | Z43: 7.1775 | AA43: 0 | AB43: 76.079687 | AC43: 1.67875 | AD43: -67.103066 | AE43: -58.58755 | AF43: -75.098856 | AG43: -66.743256
A44: 43 | B44: 2024 | C44: 1 | D44: 3 | E44: Yes | F44: Yes | G44: No | H44: No | I44: No | J44: 5381.1 | K44: 6034 | L44: 1966.6 | M44: =SUM(J44:L44) -> 13381.7 | N44: 41.511823 | O44: 70.570099 | P44: 27.674549 | Q44: 56.456079 | R44: 98.08155 | S44: 112.40313 | T44: 78.689687 | U44: 5.3921875 | V44: 0 | W44: 41.8325 | X44: 15.4425 | Y44: 7.83 | Z44: 8.1925 | AA44: 0 | AB44: 78.689687 | AC44: 1.67875 | AD44: -56.569726 | AE44: -41.833029 | AF44: -70.407001 | AG44: -55.947049
A45: 44 | B45: 2024 | C45: 1 | D45: 4 | E45: Yes | F45: Yes | G45: No | H45: No | I45: No | J45: 4159.9 | K45: 4460.7 | L45: 1432.6 | M45: =SUM(J45:L45) -> 10053.2 | N45: 31.513461 | O45: 53.572883 | P45: 21.008974 | Q45: 42.858307 | R45: 106.21046 | S45: 117.0826 | T45: 89.318188 | U45: 5.3921875 | V45: 0 | W45: 55.4625 | X45: 14.471 | Y45: 6.3075 | Z45: 7.685 | AA45: 0 | AB45: 89.318188 | AC45: 1.67875 | AD45: -74.696998 | AE45: -63.50972 | AF45: -85.201485 | AG45: -74.224296
A46: 45 | B46: 2024 | C46: 2 | D46: 1 | E46: Yes | F46: Yes | G46: Yes | H46: No | I46: No | J46: 3708 | K46: 6510 | L46: 1006.7 | M46: =SUM(J46:L46) -> 11224.7 | N46: 30.994247 | O46: 52.690219 | P46: 20.662831 | Q46: 42.152175 | R46: 95.749655 | S46: 106.44267 | T46: 76.587188 | U46: 5.3921875 | V46: 0.435 | W46: 44.2975 | X46: 11.0925 | Y46: 8.0475 | Z46: 7.3225 | AA46: 0 | AB46: 76.587188 | AC46: 4.07875 | AD46: -64.755409 | AE46: -53.752451 | AF46: -75.086824 | AG46: -64.290495
A47: 46 | B47: 2024 | C47: 2 | D47: 2 | E47: Yes | F47: Yes | G47: Yes | H47: No | I47: No | J47: 3844.7 | K47: 4290 | L47: 821.5 | M47: =SUM(J47:L47) -> 8956.2 | N47: 27.794645 | O47: 47.250896 | P47: 18.529763 | Q47: 37.800717 | R47: 86.829755 | S47: 96.418907 | T47: 68.467187 | U47: 5.3921875 | V47: 0.435 | W47: 39.295 | X47: 12.47 | Y47: 4.785 | Z47: 6.09 | AA47: 0 | AB47: 68.467187 | AC47: 4.07875 | AD47: -59.03511 | AE47: -49.168011 | AF47: -68.299992 | AG47: -58.618191
A48: 47 | B48: 2024 | C48: 2 | D48: 3 | E48: Yes | F48: Yes | G48: Yes | H48: No | I48: No | J48: 3178.7 | K48: 6220.2 | L48: 1054.5 | M48: =SUM(J48:L48) -> 10453.4 | N48: 28.118786 | O48: 47.801937 | P48: 18.745857 | Q48: 38.241549 | R48: 94.95829 | S48: 104.65927 | T48: 76.514687 | U48: 5.3921875 | V48: 0.435 | W48: 45.7475 | X48: 11.02 | Y48: 6.96 | Z48: 6.96 | AA48: 0 | AB48: 76.514687 | AC48: 4.07875 | AD48: -66.839504 | AE48: -56.857335 | AF48: -76.212433 | AG48: -66.417722
A49: 48 | B49: 2024 | C49: 2 | D49: 4 | E49: Yes | F49: Yes | G49: Yes | H49: No | I49: No | J49: 6492.1 | K49: 10110.9 | L49: 1051.6 | M49: =SUM(J49:L49) -> 17654.6 | N49: 50.125873 | O49: 85.213984 | P49: 33.417249 | Q49: 68.171187 | R49: 109.52256 | S49: 126.81599 | T49: 85.577188 | U49: 5.3921875 | V49: 0.435 | W49: 45.1675 | X49: 19.575 | Y49: 9.135 | Z49: 5.8725 | AA49: 0 | AB49: 85.577188 | AC49: 4.07875 | AD49: -59.396689 | AE49: -41.602004 | AF49: -76.105313 | AG49: -58.644801
A50: 49 | B50: 2024 | C50: 3 | D50: 1 | E50: No | F50: Yes | G50: Yes | H50: Yes | I50: No | J50: 1802.8 | K50: 5757.4 | L50: 728.3 | M50: =SUM(J50:L50) -> 8288.5 | N50: 45.974115 | O50: 82.753406 | P50: 30.64941 | Q50: 66.202725 | R50: 128.03671 | S50: 145.50687 | T50: 81.058021 | U50: 7.6880208 | V50: 0.435 | W50: 51.475 | X50: 7.395 | Y50: 6.96 | Z50: 7.105 | AA50: 0 | AB50: 81.058021 | AC50: 28.15 | AD50: -82.062591 | AE50: -62.753463 | AF50: -97.387296 | AG50: -79.304144
A51: 50 | B51: 2024 | C51: 3 | D51: 2 | E51: No | F51: Yes | G51: Yes | H51: Yes | I51: No | J51: 2525 | K51: 2891.7 | L51: 1496 | M51: =SUM(J51:L51) -> 6912.7 | N51: 40.892709 | O51: 73.606876 | P51: 27.261806 | Q51: 58.885501 | R51: 110.96135 | S51: 126.50058 | T51: 65.253021 | U51: 7.6880208 | V51: 0.435 | W51: 36.6125 | X51: 9.3525 | Y51: 3.48 | Z51: 7.685 | AA51: 0 | AB51: 65.253021 | AC51: 28.15 | AD51: -70.068645 | AE51: -52.893708 | AF51: -83.699548 | AG51: -67.615083
A52: 51 | B52: 2024 | C52: 3 | D52: 3 | E52: No | F52: Yes | G52: Yes | H52: Yes | I52: No | J52: 5394.5 | K52: 1942.5 | L52: 2180.2 | M52: =SUM(J52:L52) -> 9517.2 | N52: 59.258706 | O52: 106.66567 | P52: 39.505804 | Q52: 85.332537 | R52: 122.36785 | S52: 144.88616 | T52: 72.068021 | U52: 7.6880208 | V52: 0.435 | W52: 37.3375 | X52: 16.24 | Y52: 1.74 | Z52: 8.6275 | AA52: 0 | AB52: 72.068021 | AC52: 28.15 | AD52: -63.109147 | AE52: -38.220491 | AF52: -82.862049 | AG52: -59.553625
...

Sheet TIP Benchmarks (R)
A1: class | B1: year | C1: expenses | D1: margin
A2: 0-50 | B2: 2018-2022 | C2: 1.3155 | D2: -0.3155
A3: 0-50 | B3: 2023 | C3: 2.3363 | D3: -1.3363
A4: 50-100 | B4: 2018-2022 | C4: 1.0338 | D4: -0.0338
A5: 50-100 | B5: 2023 | C5: 1.5408 | D5: -0.5408
A6: 100-500 | B6: 2018-2022 | C6: 0.8759 | D6: 0.11
A7: 100-500 | B7: 2023 | C7: 0.9264 | D7: 0.0736
A8: 500-1M | B8: 2018-2022 | C8: 0.8516 | D8: 0.1484
A9: 500-1M | B9: 2023 | C9: 0.8751 | D9: 0.125
A10: 1M+ | B10: 2018-2022 | C10: 0.9092 | D10: 0.0748
A11: 1M+ | B11: 2023 | C11: 0.9397 | D11: 0.0603

Sheet Cost-Benefit Analysis 2022
B1: Treatment 1-1 | C1: Treatment 1-2 | D1: Treatment 1-3 | E1: Treatment 1-4 | F1: Treatment 2-1 | G1: Treatment 2-2 | H1: Treatment 2-3 | I1: Treatment 2-4 | J1: Treatment 3-1 | K1: Treatment 3-2 | L1: Treatment 3-3 | M1: Treatment 3-4 | N1: Treatment 4-1 | O1: Treatment 4-2 | P1: Treatment 4-3 | Q1: Treatment 4-4 | R1: Treatment 5-1 | S1: Treatment 5-2 | T1: Treatment 5-3 | U1: Treatment 5-4 | V1: TOTAL
A2: REVENUE
A3: Bean Revenue (2.5 x 1 m) - WHOLESALE | B3: ='Crop Revenue (2022-2024)'!C5 -> 14.622403 | C3: ='Crop Revenue (2022-2024)'!D5 -> 16.728879 | D3: ='Crop Revenue (2022-2024)'!E5 -> 14.764696 | E3: ='Crop Revenue (2022-2024)'!F5 -> 17.18953 | F3: ='Crop Revenue (2022-2024)'!G5 -> 11.75628 | G3: ='Crop Revenue (2022-2024)'!H5 -> 12.854097 | H3: ='Crop Revenue (2022-2024)'!I5 -> 11.684233 | I3: ='Crop Revenue (2022-2024)'!J5 -> 17.522747 | ... U3: ='Crop Revenue (2022-2024)'!V5 -> 25.236231 | V3: =SUM(B3:U3) -> 338.78516
A4: Carrot Revenue (2.5 x 1 m) - WHOLESALE | B4: ='Crop Revenue (2022-2024)'!C17 -> 3.0071692 | C4: ='Crop Revenue (2022-2024)'!D17 -> 8.5709307 | D4: ='Crop Revenue (2022-2024)'!E17 -> 3.3149714 | E4: ='Crop Revenue (2022-2024)'!F17 -> 7.3439942 | F4: ='Crop Revenue (2022-2024)'!G17 -> 5.6711095 | G4: ='Crop Revenue (2022-2024)'!H17 -> 4.5547255 | H4: ='Crop Revenue (2022-2024)'!I17 -> 7.8762838 | I4: ='Crop Revenue (2022-2024)'!J17 -> 4.4041178 | ... U4: ='Crop Revenue (2022-2024)'!V17 -> 13.890351 | V4: =SUM(B4:U4) -> 169.82538
A5: Kale Revenue (2.5 x 1 m) - WHOLESALE | B5: ='Crop Revenue (2022-2024)'!C29 -> 0.089383117 | C5: ='Crop Revenue (2022-2024)'!D29 -> 0.14739335 | D5: ='Crop Revenue (2022-2024)'!E29 -> 0.14354573 | E5: ='Crop Revenue (2022-2024)'!F29 -> 0.16781532 | F5: ='Crop Revenue (2022-2024)'!G29 -> 0.18498162 | G5: ='Crop Revenue (2022-2024)'!H29 -> 0.0754725 | H5: ='Crop Revenue (2022-2024)'!I29 -> 0.16041606 | I5: ='Crop Revenue (2022-2024)'!J29 -> 0.089975058 | ... U5: ='Crop Revenue (2022-2024)'!V29 -> 0.51943995 | V5: =SUM(B5:U5) -> 5.663174
A6: Bean Revenue (2.5 x 1 m) - DIRECT MARKETING | B6: ='Crop Revenue (2022-2024)'!C41 -> 24.858084 | C6: ='Crop Revenue (2022-2024)'!D41 -> 28.439094 | D6: ='Crop Revenue (2022-2024)'!E41 -> 25.099982 | E6: ='Crop Revenue (2022-2024)'!F41 -> 29.2222 | F6: ='Crop Revenue (2022-2024)'!G41 -> 19.985676 | G6: ='Crop Revenue (2022-2024)'!H41 -> 21.851966 | H6: ='Crop Revenue (2022-2024)'!I41 -> 19.863196 | I6: ='Crop Revenue (2022-2024)'!J41 -> 29.78867 | ... U6: ='Crop Revenue (2022-2024)'!V41 -> 45.425216 | V6: =SUM(B6:U6) -> 598.101
A7: Carrot Revenue (2.5 x 1 m) - DIRECT MARKETING | B7: ='Crop Revenue (2022-2024)'!C53 -> 5.1121876 | C7: ='Crop Revenue (2022-2024)'!D53 -> 14.570582 | D7: ='Crop Revenue (2022-2024)'!E53 -> 5.6354514 | E7: ='Crop Revenue (2022-2024)'!F53 -> 12.48479 | F7: ='Crop Revenue (2022-2024)'!G53 -> 9.6408862 | G7: ='Crop Revenue (2022-2024)'!H53 -> 7.7430334 | H7: ='Crop Revenue (2022-2024)'!I53 -> 13.389683 | I7: ='Crop Revenue (2022-2024)'!J53 -> 7.4870003 | ... U7: ='Crop Revenue (2022-2024)'!V53 -> 25.002632 | V7: =SUM(B7:U7) -> 301.21135
A8: Kale Revenue (2.5 x 1 m) - DIRECT MARKETING | B8: ='Crop Revenue (2022-2024)'!C65 -> 0.1519513 | C8: ='Crop Revenue (2022-2024)'!D65 -> 0.2505687 | D8: ='Crop Revenue (2022-2024)'!E65 -> 0.24402775 | E8: ='Crop Revenue (2022-2024)'!F65 -> 0.28528605 | F8: ='Crop Revenue (2022-2024)'!G65 -> 0.31446875 | G8: ='Crop Revenue (2022-2024)'!H65 -> 0.12830325 | H8: ='Crop Revenue (2022-2024)'!I65 -> 0.2727073 | I8: ='Crop Revenue (2022-2024)'!J65 -> 0.1529576 | ... U8: ='Crop Revenue (2022-2024)'!V65 -> 0.93499192 | V8: =SUM(B8:U8) -> 10.087815
A9: Livestock Revenue | B9: 0 | C9: 0 | D9: 0 | E9: 0 | F9: 0 | G9: 0 | H9: 0 | I9: 0 | J9: 0 | K9: 0 | L9: 0 | M9: 0 | N9: 0 | O9: 0 | P9: 0 | Q9: 0 | R9: 0 | S9: 0 | T9: 0 | U9: 0 | V9: =SUM(B9:U9) -> 0
A10: TOTAL REVENUE - WHOLESALE | B10: =SUM(B3:B5,B9) -> 17.718955 | C10: =SUM(C3:C5,C9) -> 25.447203 | D10: =SUM(D3:D5,D9) -> 18.223213 | E10: =SUM(E3:E5,E9) -> 24.701339 | F10: =SUM(F3:F5,F9) -> 17.612371 | G10: =SUM(G3:G5,G9) -> 17.484295 | H10: =SUM(H3:H5,H9) -> 19.720933 | I10: =SUM(I3:I5,I9) -> 22.01684 | ... U10: =SUM(U3:U5,U9) -> 39.646022 | V10: =SUM(B10:U10) -> 514.27371
A11: TOTAL REVENUE - DIRECT MARKETING | B11: =SUM(B6:B9) -> 30.122223 | C11: =SUM(C6:C9) -> 43.260245 | D11: =SUM(D6:D9) -> 30.979462 | E11: =SUM(E6:E9) -> 41.992277 | F11: =SUM(F6:F9) -> 29.941031 | G11: =SUM(G6:G9) -> 29.723302 | H11: =SUM(H6:H9) -> 33.525586 | I11: =SUM(I6:I9) -> 37.428628 | ... U11: =SUM(U6:U9) -> 71.36284 | V11: =SUM(B11:U11) -> 909.40016
A12: TOTAL REVENUE - WHOLESALE WITH 33% SORT-OUTS | B12: =(2/3)*B10 -> 11.812637 | C12: =(2/3)*C10 -> 16.964802 | D12: =(2/3)*D10 -> 12.148808 | E12: =(2/3)*E10 -> 16.467559 | F12: =(2/3)*F10 -> 11.741581 | G12: =(2/3)*G10 -> 11.656197 | H12: =(2/3)*H10 -> 13.147289 | I12: =(2/3)*I10 -> 14.677894 | ... U12: =(2/3)*U10 -> 26.430682 | V12: =SUM(B12:U12) -> 342.84914
A13: TOTAL REVENUE - DIRECT MARKETING WITH 20% UNSOLD | B13: =0.8*B11 -> 24.097779 | C13: =0.8*C11 -> 34.608196 | D13: =0.8*D11 -> 24.783569 | E13: =0.8*E11 -> 33.593821 | F13: =0.8*F11 -> 23.952825 | G13: =0.8*G11 -> 23.778642 | H13: =0.8*H11 -> 26.820469 | I13: =0.8*I11 -> 29.942903 | ... U13: =0.8*U11 -> 57.090272 | V13: =SUM(B13:U13) -> 727.52013
A15: ANNUAL VARIABLE COST | B15: =AVERAGE(B10:E10) -> 21.522677
A16: TOTAL LAND PREPARATION COST
A17: Machine Cost - Land Preparation | B17: ='Land Prep Costs (2022-2024)'!$I$10 -> 1.2458333 | C17: ='Land Prep Costs (2022-2024)'!$I$10 -> 1.2458333 | D17: ='Land Prep Costs (2022-2024)'!$I$10 -> 1.2458333 | E17: ='Land Prep Costs (2022-2024)'!$I$10 -> 1.2458333 | F17: ='Land Prep Costs (2022-2024)'!$I$10 -> 1.2458333 | G17: ='Land Prep Costs (2022-2024)'!$I$10 -> 1.2458333 | H17: ='Land Prep Costs (2022-2024)'!$I$10 -> 1.2458333 | I17: ='Land Prep Costs (2022-2024)'!$I$10 -> 1.2458333 | ... U17: ='Land Prep Costs (2022-2024)'!$I$10 -> 1.2458333 | V17: =SUM(B17:U17) -> 24.916667 | X17: Questions
A18: Labour Cost - Land Preparation | B18: ='Land Prep Costs (2022-2024)'!$I$29 -> 7.1077083 | C18: ='Land Prep Costs (2022-2024)'!$I$29 -> 7.1077083 | D18: ='Land Prep Costs (2022-2024)'!$I$29 -> 7.1077083 | E18: ='Land Prep Costs (2022-2024)'!$I$29 -> 7.1077083 | F18: ='Land Prep Costs (2022-2024)'!$I$29 -> 7.1077083 | G18: ='Land Prep Costs (2022-2024)'!$I$29 -> 7.1077083 | H18: ='Land Prep Costs (2022-2024)'!$I$29 -> 7.1077083 | I18: ='Land Prep Costs (2022-2024)'!$I$29 -> 7.1077083 | J18: ='Land Prep Costs (2022-2024)'!$I$30 -> 8.411875 | K18: ='Land Prep Costs (2022-2024)'!$I$30 -> 8.411875 | L18: ='Land Prep Costs (2022-2024)'!$I$30 -> 8.411875 | M18: ='Land Prep Costs (2022-2024)'!$I$30 -> 8.411875 | N18: ='Land Prep Costs (2022-2024)'!$I$30 -> 8.411875 | O18: ='Land Prep Costs (2022-2024)'!$I$30 -> 8.411875 | P18: ='Land Prep Costs (2022-2024)'!$I$30 -> 8.411875 | Q18: ='Land Prep Costs (2022-2024)'!$I$30 -> 8.411875 | ... U18: ='Land Prep Costs (2022-2024)'!$I$30 -> 8.411875 | V18: =SUM(B18:U18) -> 157.80417 | X18: 1. What about weed whacking and mower use? Also for carrying crops
A19: Fuel | B19: ='Costs (2022-2024)'!$I$16 -> 1 | C19: ='Costs (2022-2024)'!$I$16 -> 1 | D19: ='Costs (2022-2024)'!$I$16 -> 1 | E19: ='Costs (2022-2024)'!$I$16 -> 1 | F19: ='Costs (2022-2024)'!$I$16 -> 1 | G19: ='Costs (2022-2024)'!$I$16 -> 1 | H19: ='Costs (2022-2024)'!$I$16 -> 1 | I19: ='Costs (2022-2024)'!$I$16 -> 1 | ... U19: ='Costs (2022-2024)'!$I$16 -> 1 | V19: =SUM(B19:U19) -> 20 | X19: 2. How do I quantify sheep revenue?
A20: TOTAL FERTILITY & NUTRIENT COST | X20: 3. What about fuel costs?
A21: Inorganic Fertilizer | B21: ='Costs (2022-2024)'!$I$9 -> 1.67875 | C21: ='Costs (2022-2024)'!$I$9 -> 1.67875 | D21: ='Costs (2022-2024)'!$I$9 -> 1.67875 | E21: ='Costs (2022-2024)'!$I$9 -> 1.67875 | F21: ='Costs (2022-2024)'!$I$9 -> 1.67875 | G21: ='Costs (2022-2024)'!$I$9 -> 1.67875 | H21: ='Costs (2022-2024)'!$I$9 -> 1.67875 | I21: ='Costs (2022-2024)'!$I$9 -> 1.67875 | J21: 0 | K21: 0 | L21: 0 | M21: 0 | N21: 0 | O21: 0 | P21: 0 | Q21: 0 | R21: 0 | S21: 0 | T21: 0 | U21: 0 | V21: =SUM(B21:U21) -> 13.43 | X21: 4. What about post-harvest?
A22: Compost | B22: 0 | C22: 0 | D22: 0 | E22: 0 | F22: 0 | G22: 0 | H22: 0 | I22: 0 | J22: =243/12 -> 20.25 | K22: =243/12 -> 20.25 | L22: =243/12 -> 20.25 | M22: =243/12 -> 20.25 | N22: =243/12 -> 20.25 | O22: =243/12 -> 20.25 | P22: =243/12 -> 20.25 | Q22: =243/12 -> 20.25 | ... U22: =243/12 -> 20.25 | V22: =SUM(B22:U22) -> 243
A23: TOTAL SEED COST
A24: Cover Crop Seeds | B24: 0 | C24: 0 | D24: 0 | E24: 0 | F24: ='Costs (2022-2024)'!$I$6 -> 2.885 | G24: ='Costs (2022-2024)'!$I$6 -> 2.885 | H24: ='Costs (2022-2024)'!$I$6 -> 2.885 | I24: ='Costs (2022-2024)'!$I$6 -> 2.885 | J24: ='Costs (2022-2024)'!$I$6 -> 2.885 | K24: ='Costs (2022-2024)'!$I$6 -> 2.885 | L24: ='Costs (2022-2024)'!$I$6 -> 2.885 | M24: ='Costs (2022-2024)'!$I$6 -> 2.885 | ... U24: ='Costs (2022-2024)'!$I$6 -> 2.885 | V24: =SUM(B24:U24) -> 46.16
A25: TOTAL PLANTING COST
A26: Labour Cost - Planting | B26: ='Labour Costs (2022-2024)'!C4 -> 0 | C26: ='Labour Costs (2022-2024)'!D4 -> 0 | D26: ='Labour Costs (2022-2024)'!E4 -> 0 | E26: ='Labour Costs (2022-2024)'!F4 -> 0 | F26: ='Labour Costs (2022-2024)'!G4 -> 0.39125 | G26: ='Labour Costs (2022-2024)'!H4 -> 0.39125 | H26: ='Labour Costs (2022-2024)'!I4 -> 0.39125 | I26: ='Labour Costs (2022-2024)'!J4 -> 0.39125 | ... U26: ='Labour Costs (2022-2024)'!V4 -> 0.39125 | V26: =SUM(B26:U26) -> 6.26
A27: TOTAL WEEDING & PEST MANAGEMENT COST
A28: Labour Cost - Weeding | B28: ='Labour Costs (2022-2024)'!C11 -> 11.998333 | C28: ='Labour Costs (2022-2024)'!D11 -> 10.1725 | D28: ='Labour Costs (2022-2024)'!E11 -> 13.041667 | E28: ='Labour Costs (2022-2024)'!F11 -> 18.519167 | F28: ='Labour Costs (2022-2024)'!G11 -> 11.998333 | G28: ='Labour Costs (2022-2024)'!H11 -> 18.258333 | H28: ='Labour Costs (2022-2024)'!I11 -> 16.954167 | I28: ='Labour Costs (2022-2024)'!J11 -> 11.7375 | ... U28: ='Labour Costs (2022-2024)'!V11 -> 8.8683333 | V28: =SUM(B28:U28) -> 327.34583
A29: TOTAL HARVEST COST
A30: Labour Cost - Bean Harvest | B30: ='Labour Costs (2022-2024)'!C20 -> 4.9558333 | C30: ='Labour Costs (2022-2024)'!D20 -> 5.4775 | D30: ='Labour Costs (2022-2024)'!E20 -> 4.695 | E30: ='Labour Costs (2022-2024)'!F20 -> 5.4775 | F30: ='Labour Costs (2022-2024)'!G20 -> 3.9125 | G30: ='Labour Costs (2022-2024)'!H20 -> 4.4341667 | H30: ='Labour Costs (2022-2024)'!I20 -> 4.1733333 | I30: ='Labour Costs (2022-2024)'!J20 -> 6.26 | ... U30: ='Labour Costs (2022-2024)'!V20 -> 5.2166667 | V30: =SUM(B30:U30) -> 85.553333 | AJ30: ='Crop Prices (2022-2024)'!I15/'Crop Prices (2022-2024)'!D15 -> 3.27
A31: Labour Cost - Carrot Harvest | B31: ='Labour Costs (2022-2024)'!C21 -> 1.0433333 | C31: ='Labour Costs (2022-2024)'!D21 -> 4.4341667 | D31: ='Labour Costs (2022-2024)'!E21 -> 3.3908333 | E31: ='Labour Costs (2022-2024)'!F21 -> 3.6516667 | F31: ='Labour Costs (2022-2024)'!G21 -> 2.3475 | G31: ='Labour Costs (2022-2024)'!H21 -> 2.0866667 | H31: ='Labour Costs (2022-2024)'!I21 -> 2.6083333 | I31: ='Labour Costs (2022-2024)'!J21 -> 1.8258333 | ... U31: ='Labour Costs (2022-2024)'!V21 -> 1.3041667 | V31: =SUM(B31:U31) -> 37.299167
A32: Labour Cost - Kale Harvest | B32: ='Labour Costs (2022-2024)'!C22 -> 0.45645833 | C32: ='Labour Costs (2022-2024)'!D22 -> 0.52166667 | D32: ='Labour Costs (2022-2024)'!E22 -> 0.39125 | E32: ='Labour Costs (2022-2024)'!F22 -> 0.45645833 | F32: ='Labour Costs (2022-2024)'!G22 -> 0.39125 | G32: ='Labour Costs (2022-2024)'!H22 -> 0.45645833 | H32: ='Labour Costs (2022-2024)'!I22 -> 0.32604167 | I32: ='Labour Costs (2022-2024)'!J22 -> 0.45645833 | ... U32: ='Labour Costs (2022-2024)'!V22 -> 0.7825 | V32: =SUM(B32:U32) -> 9.4552083
A33: TOTAL LIVESTOCK COST
A34: Labour Cost - Livestock Management | B34: ='Labour Costs (2022-2024)'!C37 -> 0 | C34: ='Labour Costs (2022-2024)'!D37 -> 0 | D34: ='Labour Costs (2022-2024)'!E37 -> 0 | E34: ='Labour Costs (2022-2024)'!F37 -> 0 | F34: ='Labour Costs (2022-2024)'!G37 -> 0 | G34: ='Labour Costs (2022-2024)'!H37 -> 0 | H34: ='Labour Costs (2022-2024)'!I37 -> 0 | I34: ='Labour Costs (2022-2024)'!J37 -> 0 | ... U34: ='Labour Costs (2022-2024)'!V37 -> 0 | V34: =SUM(B34:U34) -> 0
A35: Equipment - Livestock | B35: 0 | C35: 0 | D35: 0 | E35: 0 | F35: 0 | G35: 0 | H35: 0 | I35: 0 | J35: 0 | K35: 0 | L35: 0 | M35: 0 | N35: 0 | O35: 0 | P35: 0 | Q35: 0 | R35: 0 | S35: 0 | T35: 0 | U35: 0 | V35: =SUM(B35:U35) -> 0
A36: Livestock Cost | B36: 0 | C36: 0 | D36: 0 | E36: 0 | F36: 0 | G36: 0 | H36: 0 | I36: 0 | J36: 0 | K36: 0 | L36: 0 | M36: 0 | N36: 0 | O36: 0 | P36: 0 | Q36: 0 | R36: 0 | S36: 0 | T36: 0 | U36: 0 | V36: =SUM(B36:U36) -> 0
A37: TOTAL MARKETING COST
A38: Associated Marketing Costs - Wholesale (25% of Total Revenue) | B38: =B10*0.25 -> 4.4297387 | C38: =C10*0.25 -> 6.3618007 | D38: =D10*0.25 -> 4.5558032 | E38: =E10*0.25 -> 6.1753348 | F38: =F10*0.25 -> 4.4030928 | G38: =G10*0.25 -> 4.3710739 | H38: =H10*0.25 -> 4.9302333 | I38: =I10*0.25 -> 5.5042101 | ... U38: =U10*0.25 -> 9.9115056 | V38: =SUM(B38:U38) -> 128.56843
A39: Associated Marketing Costs - Direct Marketing (35% of Total Revenue) | B39: =B11*0.35 -> 10.542778 | C39: =C11*0.35 -> 15.141086 | D39: =D11*0.35 -> 10.842812 | E39: =E11*0.35 -> 14.697297 | F39: =F11*0.35 -> 10.479361 | G39: =G11*0.35 -> 10.403156 | H39: =H11*0.35 -> 11.733955 | I39: =I11*0.35 -> 13.10002 | ... U39: =U11*0.35 -> 24.976994 | V39: =SUM(B39:U39) -> 318.29006 | W39: Note: I figured that total marketing costs will be 25% of the annual variable cost.
A40: TOTAL INPUT COST | B40: =SUM(B21,B22,B24) -> 1.67875 | C40: =SUM(C21,C22,C24) -> 1.67875 | D40: =SUM(D21,D22,D24) -> 1.67875 | E40: =SUM(E21,E22,E24) -> 1.67875 | F40: =SUM(F21,F22,F24) -> 4.56375 | G40: =SUM(G21,G22,G24) -> 4.56375 | H40: =SUM(H21,H22,H24) -> 4.56375 | I40: =SUM(I21,I22,I24) -> 4.56375 | ... U40: =SUM(U21,U22,U24) -> 23.135 | V40: =SUM(B40:U40) -> 302.59
A41: TOTAL ANNUAL LABOUR COST - WHOLESALE | B41: =SUM(B18+B26+B28+B30+B31+B32+B34) -> 25.561667 | C41: =SUM(C18+C26+C28+C30+C31+C32+C34) -> 27.713542 | D41: =SUM(D18+D26+D28+D30+D31+D32+D34) -> 28.626458 | E41: =SUM(E18+E26+E28+E30+E31+E32+E34) -> 35.2125 | F41: =SUM(F18+F26+F28+F30+F31+F32+F34) -> 26.148542 | G41: =SUM(G18+G26+G28+G30+G31+G32+G34) -> 32.734583 | H41: =SUM(H18+H26+H28+H30+H31+H32+H34) -> 31.560833 | I41: =SUM(I18+I26+I28+I30+I31+I32+I34) -> 27.77875 | ... U41: =SUM(U18+U26+U28+U30+U31+U32+U34) -> 24.974792 | V41: =SUM(B41:U41) -> 623.71771
...

Sheet Cost-Benefit Analysis 2023
B1: Treatment 1-1 | C1: Treatment 1-2 | D1: Treatment 1-3 | E1: Treatment 1-4 | F1: Treatment 2-1 | G1: Treatment 2-2 | H1: Treatment 2-3 | I1: Treatment 2-4 | J1: Treatment 3-1 | K1: Treatment 3-2 | L1: Treatment 3-3 | M1: Treatment 3-4 | N1: Treatment 4-1 | O1: Treatment 4-2 | P1: Treatment 4-3 | Q1: Treatment 4-4 | R1: Treatment 5-1 | S1: Treatment 5-2 | T1: Treatment 5-3 | U1: Treatment 5-4 | V1: TOTAL
A2: REVENUE
A3: Bean Revenue (2.5 x 1 m) - WHOLESALE | B3: ='Crop Revenue (2022-2024)'!C8 -> 21.917611 | C3: ='Crop Revenue (2022-2024)'!D8 -> 26.451024 | D3: ='Crop Revenue (2022-2024)'!E8 -> 37.073482 | E3: ='Crop Revenue (2022-2024)'!F8 -> 23.572409 | F3: ='Crop Revenue (2022-2024)'!G8 -> 20.702853 | G3: ='Crop Revenue (2022-2024)'!H8 -> 34.599152 | H3: ='Crop Revenue (2022-2024)'!I8 -> 29.859784 | I3: ='Crop Revenue (2022-2024)'!J8 -> 33.117891 | ... U3: ='Crop Revenue (2022-2024)'!V8 -> 55.954893 | V3: =SUM(B3:U3) -> 777.32225
A4: Carrot Revenue (2.5 x 1 m) - WHOLESALE | B4: ='Crop Revenue (2022-2024)'!C20 -> 7.9533423 | C4: ='Crop Revenue (2022-2024)'!D20 -> 13.578387 | D4: ='Crop Revenue (2022-2024)'!E20 -> 14.422656 | E4: ='Crop Revenue (2022-2024)'!F20 -> 11.945178 | F4: ='Crop Revenue (2022-2024)'!G20 -> 12.668954 | G4: ='Crop Revenue (2022-2024)'!H20 -> 10.223238 | H4: ='Crop Revenue (2022-2024)'!I20 -> 8.5328552 | I4: ='Crop Revenue (2022-2024)'!J20 -> 12.556453 | ... U4: ='Crop Revenue (2022-2024)'!V20 -> 23.66662 | V4: =SUM(B4:U4) -> 447.85987
A5: Kale Revenue (2.5 x 1 m) - WHOLESALE | B5: ='Crop Revenue (2022-2024)'!C32 -> 1.7873614 | C5: ='Crop Revenue (2022-2024)'!D32 -> 5.8808777 | D5: ='Crop Revenue (2022-2024)'!E32 -> 2.8455538 | E5: ='Crop Revenue (2022-2024)'!F32 -> 3.1878711 | F5: ='Crop Revenue (2022-2024)'!G32 -> 6.2451299 | G5: ='Crop Revenue (2022-2024)'!H32 -> 2.4965896 | H5: ='Crop Revenue (2022-2024)'!I32 -> 6.3415104 | I5: ='Crop Revenue (2022-2024)'!J32 -> 4.995838 | ... U5: ='Crop Revenue (2022-2024)'!V32 -> 7.5918341 | V5: =SUM(B5:U5) -> 105.76631
A6: Bean Revenue (2.5 x 1 m) - DIRECT MARKETING | B6: ='Crop Revenue (2022-2024)'!C44 -> 37.259939 | C6: ='Crop Revenue (2022-2024)'!D44 -> 44.96674 | D6: ='Crop Revenue (2022-2024)'!E44 -> 63.02492 | E6: ='Crop Revenue (2022-2024)'!F44 -> 40.073096 | F6: ='Crop Revenue (2022-2024)'!G44 -> 35.19485 | G6: ='Crop Revenue (2022-2024)'!H44 -> 58.818558 | H6: ='Crop Revenue (2022-2024)'!I44 -> 50.761632 | I6: ='Crop Revenue (2022-2024)'!J44 -> 56.300414 | ... U6: ='Crop Revenue (2022-2024)'!V44 -> 100.71881 | V6: =SUM(B6:U6) -> 1376.4506 | X6: =6666.69-1754.04 -> 4912.65
A7: Carrot Revenue (2.5 x 1 m) - DIRECT MARKETING | B7: ='Crop Revenue (2022-2024)'!C56 -> 13.520682 | C7: ='Crop Revenue (2022-2024)'!D56 -> 23.083258 | D7: ='Crop Revenue (2022-2024)'!E56 -> 24.518516 | E7: ='Crop Revenue (2022-2024)'!F56 -> 20.306802 | F7: ='Crop Revenue (2022-2024)'!G56 -> 21.537222 | G7: ='Crop Revenue (2022-2024)'!H56 -> 17.379504 | H7: ='Crop Revenue (2022-2024)'!I56 -> 14.505854 | I7: ='Crop Revenue (2022-2024)'!J56 -> 21.34597 | ... U7: ='Crop Revenue (2022-2024)'!V56 -> 42.599917 | V7: =SUM(B7:U7) -> 796.95965 | X7: 1754.04
A8: Kale Revenue (2.5 x 1 m) - DIRECT MARKETING | B8: ='Crop Revenue (2022-2024)'!C68 -> 3.0385144 | C8: ='Crop Revenue (2022-2024)'!D68 -> 9.9974921 | D8: ='Crop Revenue (2022-2024)'!E68 -> 4.8374415 | E8: ='Crop Revenue (2022-2024)'!F68 -> 5.4193808 | F8: ='Crop Revenue (2022-2024)'!G68 -> 10.616721 | G8: ='Crop Revenue (2022-2024)'!H68 -> 4.2442023 | H8: ='Crop Revenue (2022-2024)'!I68 -> 10.780568 | I8: ='Crop Revenue (2022-2024)'!J68 -> 8.4929246 | ... U8: ='Crop Revenue (2022-2024)'!V68 -> 13.665301 | V8: =SUM(B8:U8) -> 187.00128 | X8: =X7/X6 -> 0.35704559
A9: Livestock Revenue | B9: 0 | C9: 0 | D9: 0 | E9: 0 | F9: 0 | G9: 0 | H9: 0 | I9: 0 | J9: 0 | K9: 0 | L9: 0 | M9: 0 | N9: 0 | O9: 0 | P9: 0 | Q9: 0 | R9: 0 | S9: 0 | T9: 0 | U9: 0 | V9: =SUM(B9:U9) -> 0
A10: TOTAL REVENUE - WHOLESALE | B10: =SUM(B3:B5,B9) -> 31.658315 | C10: =SUM(C3:C5,C9) -> 45.910289 | D10: =SUM(D3:D5,D9) -> 54.341693 | E10: =SUM(E3:E5,E9) -> 38.705458 | F10: =SUM(F3:F5,F9) -> 39.616937 | G10: =SUM(G3:G5,G9) -> 47.318979 | H10: =SUM(H3:H5,H9) -> 44.734149 | I10: =SUM(I3:I5,I9) -> 50.670182 | ... U10: =SUM(U3:U5,U9) -> 87.213347 | V10: =SUM(B10:U10) -> 1330.9484
A11: TOTAL REVENUE - DIRECT MARKETING | B11: =SUM(B6:B9) -> 53.819136 | C11: =SUM(C6:C9) -> 78.047491 | D11: =SUM(D6:D9) -> 92.380877 | E11: =SUM(E6:E9) -> 65.799279 | F11: =SUM(F6:F9) -> 67.348793 | G11: =SUM(G6:G9) -> 80.442264 | H11: =SUM(H6:H9) -> 76.048054 | I11: =SUM(I6:I9) -> 86.139309 | ... U11: =SUM(U6:U9) -> 156.98403 | V11: =SUM(B11:U11) -> 2360.4116
A12: TOTAL REVENUE - WHOLESALE WITH 33% SORT-OUTS | B12: =(2/3)*B10 -> 21.105543 | C12: =(2/3)*C10 -> 30.606859 | D12: =(2/3)*D10 -> 36.227795 | E12: =(2/3)*E10 -> 25.803639 | F12: =(2/3)*F10 -> 26.411291 | G12: =(2/3)*G10 -> 31.545986 | H12: =(2/3)*H10 -> 29.822766 | I12: =(2/3)*I10 -> 33.780121 | ... U12: =(2/3)*U10 -> 58.142232 | V12: =SUM(B12:U12) -> 887.29895
A13: TOTAL REVENUE - DIRECT MARKETING WITH 20% UNSOLD | B13: =0.8*B11 -> 43.055308 | C13: =0.8*C11 -> 62.437993 | D13: =0.8*D11 -> 73.904702 | E13: =0.8*E11 -> 52.639423 | F13: =0.8*F11 -> 53.879034 | G13: =0.8*G11 -> 64.353811 | H13: =0.8*H11 -> 60.838443 | I13: =0.8*I11 -> 68.911447 | ... U13: =0.8*U11 -> 125.58722 | V13: =SUM(B13:U13) -> 1888.3293
A15: ANNUAL VARIABLE COST
A16: TOTAL LAND PREPARATION COST
A17: Machine Cost - Land Preparation | B17: ='Land Prep Costs (2022-2024)'!$I$11 -> 5.8658854 | C17: ='Land Prep Costs (2022-2024)'!$I$11 -> 5.8658854 | D17: ='Land Prep Costs (2022-2024)'!$I$11 -> 5.8658854 | E17: ='Land Prep Costs (2022-2024)'!$I$11 -> 5.8658854 | F17: ='Land Prep Costs (2022-2024)'!$I$11 -> 5.8658854 | G17: ='Land Prep Costs (2022-2024)'!$I$11 -> 5.8658854 | H17: ='Land Prep Costs (2022-2024)'!$I$11 -> 5.8658854 | I17: ='Land Prep Costs (2022-2024)'!$I$11 -> 5.8658854 | ... Q17: ='Land Prep Costs (2022-2024)'!$I$11 -> 5.8658854 | R17: 0 | S17: 0 | T17: 0 | U17: 0 | V17: =SUM(B17:U17) -> 93.854167 | X17: Questions
A18: Labour Cost - Land Preparation | B18: ='Land Prep Costs (2022-2024)'!$I$31 -> 5.1907552 | C18: ='Land Prep Costs (2022-2024)'!$I$31 -> 5.1907552 | D18: ='Land Prep Costs (2022-2024)'!$I$31 -> 5.1907552 | E18: ='Land Prep Costs (2022-2024)'!$I$31 -> 5.1907552 | F18: ='Land Prep Costs (2022-2024)'!$I$31 -> 5.1907552 | G18: ='Land Prep Costs (2022-2024)'!$I$31 -> 5.1907552 | H18: ='Land Prep Costs (2022-2024)'!$I$31 -> 5.1907552 | I18: ='Land Prep Costs (2022-2024)'!$I$31 -> 5.1907552 | J18: ='Land Prep Costs (2022-2024)'!$I$32 -> 6.5865885 | K18: ='Land Prep Costs (2022-2024)'!$I$32 -> 6.5865885 | L18: ='Land Prep Costs (2022-2024)'!$I$32 -> 6.5865885 | M18: ='Land Prep Costs (2022-2024)'!$I$32 -> 6.5865885 | N18: ='Land Prep Costs (2022-2024)'!$I$33 -> 7.6334635 | O18: ='Land Prep Costs (2022-2024)'!$I$33 -> 7.6334635 | P18: ='Land Prep Costs (2022-2024)'!$I$33 -> 7.6334635 | Q18: ='Land Prep Costs (2022-2024)'!$I$33 -> 7.6334635 | R18: ='Land Prep Costs (2022-2024)'!$I$34 -> 13.522135 | S18: ='Land Prep Costs (2022-2024)'!$I$34 -> 13.522135 | T18: ='Land Prep Costs (2022-2024)'!$I$34 -> 13.522135 | U18: ='Land Prep Costs (2022-2024)'!$I$34 -> 13.522135 | V18: =SUM(B18:U18) -> 152.49479 | X18: 1. What about weed whacking and mower use? Also for carrying crops
A19: Fuel | B19: ='Costs (2022-2024)'!$I$16 -> 1 | C19: ='Costs (2022-2024)'!$I$16 -> 1 | D19: ='Costs (2022-2024)'!$I$16 -> 1 | E19: ='Costs (2022-2024)'!$I$16 -> 1 | F19: ='Costs (2022-2024)'!$I$16 -> 1 | G19: ='Costs (2022-2024)'!$I$16 -> 1 | H19: ='Costs (2022-2024)'!$I$16 -> 1 | I19: ='Costs (2022-2024)'!$I$16 -> 1 | ... U19: ='Costs (2022-2024)'!$I$16 -> 1 | V19: =SUM(B19:U19) -> 20 | X19: 2. How do I quantify sheep revenue?
A20: TOTAL FERTILITY & NUTRIENT COST | X20: 3. What about fuel costs?
A21: Inorganic Fertilizer | B21: ='Costs (2022-2024)'!$I$9 -> 1.67875 | C21: ='Costs (2022-2024)'!$I$9 -> 1.67875 | D21: ='Costs (2022-2024)'!$I$9 -> 1.67875 | E21: ='Costs (2022-2024)'!$I$9 -> 1.67875 | F21: ='Costs (2022-2024)'!$I$9 -> 1.67875 | G21: ='Costs (2022-2024)'!$I$9 -> 1.67875 | H21: ='Costs (2022-2024)'!$I$9 -> 1.67875 | I21: ='Costs (2022-2024)'!$I$9 -> 1.67875 | J21: 0 | K21: 0 | L21: 0 | M21: 0 | N21: 0 | O21: 0 | P21: 0 | Q21: 0 | R21: 0 | S21: 0 | T21: 0 | U21: 0 | V21: =SUM(B21:U21) -> 13.43 | X21: 4. What about post-harvest?
A22: Compost | B22: 0 | C22: 0 | D22: 0 | E22: 0 | F22: 0 | G22: 0 | H22: 0 | I22: 0 | J22: ='Costs (2022-2024)'!$I$13 -> 29.5 | K22: ='Costs (2022-2024)'!$I$13 -> 29.5 | L22: ='Costs (2022-2024)'!$I$13 -> 29.5 | M22: ='Costs (2022-2024)'!$I$13 -> 29.5 | N22: ='Costs (2022-2024)'!$I$13 -> 29.5 | O22: ='Costs (2022-2024)'!$I$13 -> 29.5 | P22: ='Costs (2022-2024)'!$I$13 -> 29.5 | Q22: ='Costs (2022-2024)'!$I$13 -> 29.5 | ... U22: ='Costs (2022-2024)'!$I$13 -> 29.5 | V22: =SUM(B22:U22) -> 354
A23: TOTAL SEED COST
A24: Cover Crop Seeds | B24: 0 | C24: 0 | D24: 0 | E24: 0 | F24: ='Costs (2022-2024)'!$I$7 -> 2.885 | G24: ='Costs (2022-2024)'!$I$7 -> 2.885 | H24: ='Costs (2022-2024)'!$I$7 -> 2.885 | I24: ='Costs (2022-2024)'!$I$7 -> 2.885 | J24: ='Costs (2022-2024)'!$I$7 -> 2.885 | K24: ='Costs (2022-2024)'!$I$7 -> 2.885 | L24: ='Costs (2022-2024)'!$I$7 -> 2.885 | M24: ='Costs (2022-2024)'!$I$7 -> 2.885 | ... U24: ='Costs (2022-2024)'!$I$7 -> 2.885 | V24: =SUM(B24:U24) -> 46.16
A25: TOTAL PLANTING COST
A26: Labour Cost - Planting | B26: ='Labour Costs (2022-2024)'!C6 -> 0 | C26: ='Labour Costs (2022-2024)'!D6 -> 0 | D26: ='Labour Costs (2022-2024)'!E6 -> 0 | E26: ='Labour Costs (2022-2024)'!F6 -> 0 | F26: ='Labour Costs (2022-2024)'!G6 -> 0.41875 | G26: ='Labour Costs (2022-2024)'!H6 -> 0.41875 | H26: ='Labour Costs (2022-2024)'!I6 -> 0.41875 | I26: ='Labour Costs (2022-2024)'!J6 -> 0.41875 | ... U26: ='Labour Costs (2022-2024)'!V6 -> 0.41875 | V26: =SUM(B26:U26) -> 6.7
A27: TOTAL WEEDING & PEST MANAGEMENT COST
A28: Labour Cost - Weeding | B28: ='Labour Costs (2022-2024)'!C13 -> 34.477083 | C28: ='Labour Costs (2022-2024)'!D13 -> 26.218403 | D28: ='Labour Costs (2022-2024)'!E13 -> 22.19375 | E28: ='Labour Costs (2022-2024)'!F13 -> 30.170938 | F28: ='Labour Costs (2022-2024)'!G13 -> 21.792448 | G28: ='Labour Costs (2022-2024)'!H13 -> 24.783021 | H28: ='Labour Costs (2022-2024)'!I13 -> 28.684375 | I28: ='Labour Costs (2022-2024)'!J13 -> 24.566667 | ... U28: ='Labour Costs (2022-2024)'!V13 -> 11.585417 | V28: =SUM(B28:U28) -> 505.74299
A29: TOTAL HARVEST COST
A30: Labour Cost - Bean Harvest | B30: ='Labour Costs (2022-2024)'!C26 -> 13.4 | C30: ='Labour Costs (2022-2024)'!D26 -> 12.283333 | D30: ='Labour Costs (2022-2024)'!E26 -> 15.005208 | E30: ='Labour Costs (2022-2024)'!F26 -> 11.096875 | F30: ='Labour Costs (2022-2024)'!G26 -> 9.4916667 | G30: ='Labour Costs (2022-2024)'!H26 -> 15.772917 | H30: ='Labour Costs (2022-2024)'!I26 -> 13.609375 | I30: ='Labour Costs (2022-2024)'!J26 -> 14.028125 | ... U30: ='Labour Costs (2022-2024)'!V26 -> 17.727083 | V30: =SUM(B30:U30) -> 270.86146 | AJ30: ='Crop Prices (2022-2024)'!I15/'Crop Prices (2022-2024)'!D15 -> 3.27
A31: Labour Cost - Carrot Harvest | B31: ='Labour Costs (2022-2024)'!C27 -> 4.3270833 | C31: ='Labour Costs (2022-2024)'!D27 -> 6.8395833 | D31: ='Labour Costs (2022-2024)'!E27 -> 4.6760417 | E31: ='Labour Costs (2022-2024)'!F27 -> 6.0020833 | F31: ='Labour Costs (2022-2024)'!G27 -> 5.5833333 | G31: ='Labour Costs (2022-2024)'!H27 -> 3.978125 | H31: ='Labour Costs (2022-2024)'!I27 -> 4.3270833 | I31: ='Labour Costs (2022-2024)'!J27 -> 7.3979167 | ... U31: ='Labour Costs (2022-2024)'!V27 -> 2.7916667 | V31: =SUM(B31:U31) -> 97.9875
A32: Labour Cost - Kale Harvest | B32: ='Labour Costs (2022-2024)'!C28 -> 3.0708333 | C32: ='Labour Costs (2022-2024)'!D28 -> 5.234375 | D32: ='Labour Costs (2022-2024)'!E28 -> 4.1177083 | E32: ='Labour Costs (2022-2024)'!F28 -> 4.3270833 | F32: ='Labour Costs (2022-2024)'!G28 -> 5.1645833 | G32: ='Labour Costs (2022-2024)'!H28 -> 4.5364583 | H32: ='Labour Costs (2022-2024)'!I28 -> 5.3739583 | I32: ='Labour Costs (2022-2024)'!J28 -> 4.0479167 | ... U32: ='Labour Costs (2022-2024)'!V28 -> 4.2572917 | V32: =SUM(B32:U32) -> 79.911458
A33: TOTAL LIVESTOCK COST
A34: Labour Cost - Livestock Management | B34: ='Labour Costs (2022-2024)'!C39 -> 0 | C34: ='Labour Costs (2022-2024)'!D39 -> 0 | D34: ='Labour Costs (2022-2024)'!E39 -> 0 | E34: ='Labour Costs (2022-2024)'!F39 -> 0 | F34: ='Labour Costs (2022-2024)'!G39 -> 0 | G34: ='Labour Costs (2022-2024)'!H39 -> 0 | H34: ='Labour Costs (2022-2024)'!I39 -> 0 | I34: ='Labour Costs (2022-2024)'!J39 -> 0 | ... U34: ='Labour Costs (2022-2024)'!V39 -> 10.46875 | V34: =SUM(B34:U34) -> 83.75
A35: Equipment - Livestock | B35: 0 | C35: 0 | D35: 0 | E35: 0 | F35: 0 | G35: 0 | H35: 0 | I35: 0 | J35: 0 | K35: 0 | L35: 0 | M35: 0 | N35: 0 | O35: 0 | P35: 0 | Q35: 0 | R35: 0 | S35: 0 | T35: 0 | U35: 0 | V35: =SUM(B35:U35) -> 0
A36: Livestock Cost | B36: 0 | C36: 0 | D36: 0 | E36: 0 | F36: 0 | G36: 0 | H36: 0 | I36: 0 | J36: 0 | K36: 0 | L36: 0 | M36: 0 | N36: 0 | O36: 0 | P36: 0 | Q36: 0 | R36: 0 | S36: 0 | T36: 0 | U36: 0 | V36: =SUM(B36:U36) -> 0
A37: TOTAL MARKETING COST
A38: Associated Marketing Costs - Wholesale (25% of Total Revenue) | B38: =B10*0.25 -> 7.9145788 | C38: =C10*0.25 -> 11.477572 | D38: =D10*0.25 -> 13.585423 | E38: =E10*0.25 -> 9.6763645 | F38: =F10*0.25 -> 9.9042342 | G38: =G10*0.25 -> 11.829745 | H38: =H10*0.25 -> 11.183537 | I38: =I10*0.25 -> 12.667545 | ... U38: =U10*0.25 -> 21.803337 | V38: =SUM(B38:U38) -> 332.73711
